<?xml version="1.0" ?>
<robot name="montessori_box" version="1.0">
  <link name="montessori_box">
    <inertial>
      <origin xyz="0.026771999895572662 0.00018124992493540049 -0.00393274100497365" rpy="-0.012046600691974163 -0.001452900469303131 1.56771719455719"/>
      <mass value="1.0220392942428589"/>
      <inertia ixx="0.001928424695506692" ixy="0.0" ixz="0.0" iyy="0.006246736738830805" iyz="0.0" izz="0.006575485225766897"/>
    </inertial>
    <visual name="MontessoriBox">
      <origin xyz="0.005257507786154747 1.4678141269541811e-05 -0.0003088224621023983" rpy="-1.586214542388916 -1.556058406829834 -3.1267333030700684"/>
      <geometry>
        <mesh filename="file://./stl/MontessoriBox.stl" scale="1.0 1.0 1.0"/>
      </geometry>
      <material name="MontessoriBox_material">
        <color rgba="0.89 0.67 0.57 1.0"/>
      </material>
    </visual>
  </link>

  <joint name="montessori_hole_1_joint" type="fixed">
    <origin xyz="0.025 0.091 0.04" rpy="0.0 0.0 0.0"/>
    <parent link="montessori_box"/>
    <child link="montessori_hole_1"/>
  </joint>
  <link name="montessori_hole_1" />
  <joint name="montessori_hole_2_joint" type="fixed">
    <origin xyz="0.0185 0 0.04" rpy="0.0 0.0 0.0"/>
    <parent link="montessori_box"/>
    <child link="montessori_hole_2"/>
  </joint>
  <link name="montessori_hole_2" />
  <joint name="montessori_hole_3_joint" type="fixed">
    <origin xyz="0.0205 -0.087 0.04" rpy="0.0 0.0 0.0"/>
    <parent link="montessori_box"/>
    <child link="montessori_hole_3"/>
  </joint>
  <link name="montessori_hole_3" />
  <joint name="montessori_hole_4_joint" type="fixed">
    <origin xyz="-0.0175 0.091 0.04" rpy="0.0 0.0 0.0"/>
    <parent link="montessori_box"/>
    <child link="montessori_hole_4"/>
  </joint>
  <link name="montessori_hole_4" />
  <joint name="montessori_hole_5_joint" type="fixed">
    <origin xyz="-0.0265 0 0.04" rpy="0.0 0.0 0.0"/>
    <parent link="montessori_box"/>
    <child link="montessori_hole_5"/>
  </joint>
  <link name="montessori_hole_5" />
  <joint name="montessori_hole_6_joint" type="fixed">
    <origin xyz="-0.0215 -0.087 0.04" rpy="0.0 0.0 0.0"/>
    <parent link="montessori_box"/>
    <child link="montessori_hole_6"/>
  </joint>
  <link name="montessori_hole_6" />

  <joint name="montessori_drawer_1_joint" type="prismatic">
    <origin xyz="-0.003000000026077032 0.08699999749660492 0.0" rpy="0.0 0.0 0.0"/>
    <axis xyz="-1.0 0.0 0.0"/>
    <parent link="montessori_box"/>
    <child link="montessori_drawer_1"/>
    <limit effort="1000.0" lower="0.0" upper="0.10000000149011612" velocity="1000.0"/>
  </joint>
  <link name="montessori_drawer_1">
    <inertial>
      <origin xyz="0.02574862912297249 5.7039905243527755e-08 -0.002581819426268339" rpy="-1.694860074508142e-08 0.0319184735417366 -3.294945472021027e-08"/>
      <mass value="0.13218805193901062"/>
      <inertia ixx="0.00016433888231404126" ixy="0.0" ixz="0.0" iyy="0.00020200452127028257" iyz="0.0" izz="0.000267193594481796"/>
    </inertial>
    <visual name="MontessoriDrawer1">
      <origin xyz="0.0003927545330952853 -5.131831071203408e-10 -0.004749107174575329" rpy="0.0 -1.569690227508545 3.1415927410125732"/>
      <geometry>
        <mesh filename="file://./stl/MontessoriDrawer.stl" scale="1.0 1.0 1.0"/>
      </geometry>
      <material name="MontessoriDrawer1_material">
        <color rgba="1.0 0.83 0.67 1.0"/>
      </material>
    </visual>
  </link>
  <joint name="montessori_drawer_1_handle_joint" type="fixed">
    <origin xyz="-0.061 0.0 0.001" rpy="0.0 0.0 0.0"/>
    <parent link="montessori_drawer_1"/>
    <child link="montessori_drawer_1_handle"/>
  </joint>
  <link name="montessori_drawer_1_handle">
    <inertial>
      <origin xyz="0.003915580455213785 7.503021315358183e-09 -7.799903084526605e-11" rpy="-1.570796012878418 3.2139670480546556e-08 1.3462765764415963e-06"/>
      <mass value="0.005739745683968067"/>
      <inertia ixx="2.267717889026244e-07" ixy="0.0" ixz="0.0" iyy="3.54303949734458e-07" iyz="0.0" izz="3.5472436366035254e-07"/>
    </inertial>
    <visual name="MontessoriDrawer1Handle">
      <origin xyz="0.003915580455213785 7.525752465653568e-09 -2.2858904005773617e-11" rpy="1.5707963705062866 -1.3322676295501878e-15 1.5707963705062866"/>
      <geometry>
        <mesh filename="file://./stl/MontessoriDrawerHandle.stl" scale="1.0 1.0 1.0"/>
      </geometry>
      <material name="MontessoriDrawer1Handle_material">
        <color rgba="0.89 0.67 0.57 1.0"/>
      </material>
    </visual>
  </link>
  <joint name="montessori_drawer_2_joint" type="prismatic">
    <origin xyz="-0.003000000026077032 0.0 0.0" rpy="0.0 0.0 0.0"/>
    <axis xyz="-1.0 0.0 0.0"/>
    <parent link="montessori_box"/>
    <child link="montessori_drawer_2"/>
    <limit effort="1000.0" lower="0.0" upper="0.10000000149011612" velocity="1000.0"/>
  </joint>
  <link name="montessori_drawer_2">
    <inertial>
      <origin xyz="0.02574862912297249 5.7039905243527755e-08 -0.002581819426268339" rpy="-1.694860074508142e-08 0.0319184735417366 -3.294945472021027e-08"/>
      <mass value="0.13218805193901062"/>
      <inertia ixx="0.00016433888231404126" ixy="0.0" ixz="0.0" iyy="0.00020200452127028257" iyz="0.0" izz="0.000267193594481796"/>
    </inertial>
    <visual name="MontessoriDrawer2">
      <origin xyz="0.0003927545330952853 -5.131831071203408e-10 -0.004749107174575329" rpy="0.0 -1.569690227508545 3.1415927410125732"/>
      <geometry>
        <mesh filename="file://./stl/MontessoriDrawer.stl" scale="1.0 1.0 1.0"/>
      </geometry>
      <material name="MontessoriDrawer2_material">
        <color rgba="0.99 0.73 0.55 1.0"/>
      </material>
    </visual>
  </link>
  <joint name="montessori_drawer_2_handle_joint" type="fixed">
    <origin xyz="-0.061 0.0 0.001" rpy="0.0 0.0 0.0"/>
    <parent link="montessori_drawer_2"/>
    <child link="montessori_drawer_2_handle"/>
  </joint>
  <link name="montessori_drawer_2_handle">
    <inertial>
      <origin xyz="0.003915580455213785 7.503021315358183e-09 -7.799903084526605e-11" rpy="-1.570796012878418 3.2139670480546556e-08 1.3462765764415963e-06"/>
      <mass value="0.005739745683968067"/>
      <inertia ixx="2.267717889026244e-07" ixy="0.0" ixz="0.0" iyy="3.54303949734458e-07" iyz="0.0" izz="3.5472436366035254e-07"/>
    </inertial>
    <visual name="MontessoriDrawer2Handle">
      <origin xyz="0.003915580455213785 7.525752465653568e-09 -2.2858904005773617e-11" rpy="1.5707963705062866 -1.3322676295501878e-15 1.5707963705062866"/>
      <geometry>
        <mesh filename="file://./stl/MontessoriDrawerHandle.stl" scale="1.0 1.0 1.0"/>
      </geometry>
      <material name="MontessoriDrawer2Handle_material">
        <color rgba="0.89 0.67 0.57 1.0"/>
      </material>
    </visual>
  </link>
  <joint name="montessori_drawer_3_joint" type="prismatic">
    <origin xyz="-0.003000000026077032 -0.08699999749660492 0.0" rpy="0.0 0.0 0.0"/>
    <axis xyz="-1.0 0.0 0.0"/>
    <parent link="montessori_box"/>
    <child link="montessori_drawer_3"/>
    <limit effort="1000.0" lower="0.0" upper="0.10000000149011612" velocity="1000.0"/>
  </joint>
  <link name="montessori_drawer_3">
    <inertial>
      <origin xyz="0.02574862912297249 5.7039905243527755e-08 -0.002581819426268339" rpy="-1.694860074508142e-08 0.0319184735417366 -3.294945472021027e-08"/>
      <mass value="0.13218805193901062"/>
      <inertia ixx="0.00016433888231404126" ixy="0.0" ixz="0.0" iyy="0.00020200452127028257" iyz="0.0" izz="0.000267193594481796"/>
    </inertial>
    <visual name="MontessoriDrawer3">
      <origin xyz="0.0003927545330952853 -5.131831071203408e-10 -0.004749107174575329" rpy="0.0 -1.569690227508545 3.1415927410125732"/>
      <geometry>
        <mesh filename="file://./stl/MontessoriDrawer.stl" scale="1.0 1.0 1.0"/>
      </geometry>
      <material name="MontessoriDrawer3_material">
        <color rgba="0.87 0.94 0.98 1.0"/>
      </material>
    </visual>
  </link>
  <joint name="montessori_drawer_3_handle_joint" type="fixed">
    <origin xyz="-0.061 0.0 0.001" rpy="0.0 0.0 0.0"/>
    <parent link="montessori_drawer_3"/>
    <child link="montessori_drawer_3_handle"/>
  </joint>
  <link name="montessori_drawer_3_handle">
    <inertial>
      <origin xyz="0.003915580455213785 7.503021315358183e-09 -7.799903084526605e-11" rpy="-1.570796012878418 3.2139670480546556e-08 1.3462765764415963e-06"/>
      <mass value="0.005739745683968067"/>
      <inertia ixx="2.267717889026244e-07" ixy="0.0" ixz="0.0" iyy="3.54303949734458e-07" iyz="0.0" izz="3.5472436366035254e-07"/>
    </inertial>
    <visual name="MontessoriDrawer3Handle">
      <origin xyz="0.003915580455213785 7.525752465653568e-09 -2.2858904005773617e-11" rpy="1.5707963705062866 -1.3322676295501878e-15 1.5707963705062866"/>
      <geometry>
        <mesh filename="file://./stl/MontessoriDrawerHandle.stl" scale="1.0 1.0 1.0"/>
      </geometry>
      <material name="MontessoriDrawer3Handle_material">
        <color rgba="0.89 0.67 0.57 1.0"/>
      </material>
    </visual>
  </link>
</robot>