<?xml version="1.0" ?>
<robot name="h1" version="1.0">
  <link name="h1"/>
  <joint name="pelvis_joint" type="fixed">
    <origin xyz="0.0 0.0 0.0" rpy="0.0 0.0 0.0"/>
    <parent link="h1"/>
    <child link="pelvis"/>
  </joint>
  <link name="pelvis">
    <inertial>
      <origin xyz="-0.00019999999494757503 3.9999998989515007e-05 -0.04521999880671501" rpy="-1.5486268997192383 -1.5663152933120728 3.121819257736206"/>
      <mass value="5.389999866485596"/>
      <inertia ixx="0.049021098762750626" ixy="0.0" ixz="0.0" iyy="0.044582098722457886" iyz="0.0" izz="0.008246189914643764"/>
    </inertial>
    <collision name="pelvis_collision">
      <origin xyz="0.0 0.0 -0.03999999910593033" rpy="0.0 0.0 0.0"/>
      <geometry>
        <box size="0.14000000059604645 0.30000001192092896 0.07999999821186066"/>
      </geometry>
    </collision>
  </link>
  <joint name="left_hip_yaw_joint" type="revolute">
    <origin xyz="0.0 0.08749999850988388 -0.17419999837875366" rpy="0.0 0.0 0.0"/>
    <axis xyz="0.0 0.0 1.0"/>
    <parent link="pelvis"/>
    <child link="left_hip_yaw_link"/>
    <limit effort="1000.0" lower="-0.4300000071525574" upper="0.4300000071525574" velocity="1000.0"/>
  </joint>
  <link name="left_hip_yaw_link">
    <inertial>
      <origin xyz="-0.049229998141527176 9.999999747378752e-05 0.007199999876320362" rpy="0.6504185199737549 0.04391371086239815 1.502997875213623"/>
      <mass value="2.24399995803833"/>
      <inertia ixx="0.0030449400655925274" ixy="0.0" ixz="0.0" iyy="0.002968850079923868" iyz="0.0" izz="0.0018920099828392267"/>
    </inertial>
    <collision name="left_hip_yaw_link_collision">
      <origin xyz="-0.06700000166893005 0.0 0.0" rpy="0.0 0.0 0.0"/>
      <geometry>
        <box size="0.07000000029802322 0.11999999731779099 0.11999999731779099"/>
      </geometry>
    </collision>
  </link>
  <joint name="left_hip_roll_joint" type="revolute">
    <origin xyz="0.03946800157427788 0.0 0.0" rpy="0.0 0.0 0.0"/>
    <axis xyz="1.0 0.0 0.0"/>
    <parent link="left_hip_yaw_link"/>
    <child link="left_hip_roll_link"/>
    <limit effort="1000.0" lower="-0.4300000071525574" upper="0.4300000071525574" velocity="1000.0"/>
  </joint>
  <link name="left_hip_roll_link">
    <inertial>
      <origin xyz="-0.005799999926239252 -0.0031900000758469105 -9.000000136438757e-05" rpy="-1.8351385593414307 -1.5289748907089233 -1.47176194190979"/>
      <mass value="2.2320001125335693"/>
      <inertia ixx="0.002432639943435788" ixy="0.0" ixz="0.0" iyy="0.0022532499860972166" iyz="0.0" izz="0.0020549199543893337"/>
    </inertial>
    <collision name="left_hip_roll_link_collision">
      <origin xyz="0.0 0.0 0.0" rpy="0.0 0.0 0.0"/>
      <geometry>
        <box size="0.11999999731779099 0.11999999731779099 0.11999999731779099"/>
      </geometry>
    </collision>
  </link>
  <joint name="left_hip_pitch_joint" type="revolute">
    <origin xyz="0.0 0.11535999923944473 0.0" rpy="0.0 0.0 0.0"/>
    <axis xyz="0.0 1.0 0.0"/>
    <parent link="left_hip_roll_link"/>
    <child link="left_hip_pitch_link"/>
    <limit effort="1000.0" lower="-3.140000104904175" upper="2.5300002098083496" velocity="1000.0"/>
  </joint>
  <link name="left_hip_pitch_link">
    <inertial>
      <origin xyz="0.007459999993443489 -0.02346000075340271 -0.0819299966096878" rpy="0.10738416016101837 -0.01352748367935419 -0.3884797990322113"/>
      <mass value="4.1519999504089355"/>
      <inertia ixx="0.08295030146837234" ixy="0.0" ixz="0.0" iyy="0.08214569836854935" iyz="0.0" izz="0.005109089892357588"/>
    </inertial>
    <collision name="left_hip_pitch_link_collision">
      <origin xyz="0.0 -0.009999999776482582 -0.1899999976158142" rpy="0.0 0.0 0.0"/>
      <geometry>
        <box size="0.11999999731779099 0.07999999821186066 0.4399999976158142"/>
      </geometry>
    </collision>
  </link>
  <joint name="left_knee_joint" type="revolute">
    <origin xyz="0.0 0.0 -0.4000000059604645" rpy="0.0 0.0 0.0"/>
    <axis xyz="0.0 1.0 0.0"/>
    <parent link="left_hip_pitch_link"/>
    <child link="left_knee_link"/>
    <limit effort="1000.0" lower="-0.2600000202655792" upper="2.049999952316284" velocity="1000.0"/>
  </joint>
  <link name="left_knee_link">
    <inertial>
      <origin xyz="-0.0013599999947473407 -0.005119999870657921 -0.13840000331401825" rpy="-0.10783059895038605 0.0011182109592482448 1.7860283851623535"/>
      <mass value="1.7209999561309814"/>
      <inertia ixx="0.012523699551820755" ixy="0.0" ixz="0.0" iyy="0.012310399673879147" iyz="0.0" izz="0.0019428000086918473"/>
    </inertial>
    <collision name="left_knee_link_collision">
      <origin xyz="0.0 -0.009999999776482582 -0.23000000417232513" rpy="0.0 0.0 0.0"/>
      <geometry>
        <box size="0.10000000149011612 0.07999999821186066 0.3400000035762787"/>
      </geometry>
    </collision>
  </link>
  <joint name="left_ankle_joint" type="revolute">
    <origin xyz="0.0 0.0 -0.4000000059604645" rpy="0.0 0.0 0.0"/>
    <axis xyz="0.0 1.0 0.0"/>
    <parent link="left_knee_link"/>
    <child link="left_ankle_link"/>
    <limit effort="1000.0" lower="-0.8700000047683716" upper="0.5200000405311584" velocity="1000.0"/>
  </joint>
  <link name="left_ankle_link">
    <inertial>
      <origin xyz="0.0485679991543293 0.0 -0.045609001070261" rpy="1.6128175258636475 0.0 1.5707963705062866"/>
      <mass value="0.5524479746818542"/>
      <inertia ixx="0.0036200000904500484" ixy="0.0" ixz="0.0" iyy="0.0035570100881159306" iyz="0.0" izz="0.00014998699771240354"/>
    </inertial>
    <collision name="left_ankle_link_collision_1">
      <origin xyz="0.14499999582767487 0.0 -0.05380000174045563" rpy="0.0 0.0 0.0"/>
      <geometry>
        <box size="0.10999999940395355 0.029600000008940697 0.029999999329447746"/>
      </geometry>
    </collision>
    <collision name="left_ankle_link_collision_2">
      <origin xyz="0.020150000229477882 0.0 -0.03999999910593033" rpy="0.0 0.0 0.0"/>
      <geometry>
        <box size="0.1396999955177307 0.029600000008940697 0.03999999910593033"/>
      </geometry>
    </collision>
    <collision name="left_ankle_link_collision_3">
      <origin xyz="-0.0746999979019165 0.0 -0.05380000174045563" rpy="0.0 0.0 0.0"/>
      <geometry>
        <box size="0.05000000074505806 0.029600000008940697 0.029999999329447746"/>
      </geometry>
    </collision>
  </link>
  <joint name="right_hip_yaw_joint" type="revolute">
    <origin xyz="0.0 -0.08749999850988388 -0.17419999837875366" rpy="0.0 0.0 0.0"/>
    <axis xyz="0.0 0.0 1.0"/>
    <parent link="pelvis"/>
    <child link="right_hip_yaw_link"/>
    <limit effort="1000.0" lower="-0.4300000071525574" upper="0.4300000071525574" velocity="1000.0"/>
  </joint>
  <link name="right_hip_yaw_link">
    <inertial>
      <origin xyz="-0.049229998141527176 -9.999999747378752e-05 0.007199999876320362" rpy="0.6504185199737549 -0.04391371086239815 1.6385948657989502"/>
      <mass value="2.24399995803833"/>
      <inertia ixx="0.0030449400655925274" ixy="0.0" ixz="0.0" iyy="0.002968850079923868" iyz="0.0" izz="0.0018920099828392267"/>
    </inertial>
    <collision name="right_hip_yaw_link_collision">
      <origin xyz="-0.06700000166893005 0.0 0.0" rpy="0.0 0.0 0.0"/>
      <geometry>
        <box size="0.07000000029802322 0.11999999731779099 0.11999999731779099"/>
      </geometry>
    </collision>
  </link>
  <joint name="right_hip_roll_joint" type="revolute">
    <origin xyz="0.03946800157427788 0.0 0.0" rpy="0.0 0.0 0.0"/>
    <axis xyz="1.0 0.0 0.0"/>
    <parent link="right_hip_yaw_link"/>
    <child link="right_hip_roll_link"/>
    <limit effort="1000.0" lower="-0.4300000071525574" upper="0.4300000071525574" velocity="1000.0"/>
  </joint>
  <link name="right_hip_roll_link">
    <inertial>
      <origin xyz="-0.005799999926239252 0.0031900000758469105 -9.000000136438757e-05" rpy="1.8351385593414307 -1.5289748907089233 1.47176194190979"/>
      <mass value="2.2320001125335693"/>
      <inertia ixx="0.002432639943435788" ixy="0.0" ixz="0.0" iyy="0.0022532499860972166" iyz="0.0" izz="0.0020549199543893337"/>
    </inertial>
    <collision name="right_hip_roll_link_collision">
      <origin xyz="0.0 0.0 0.0" rpy="0.0 0.0 0.0"/>
      <geometry>
        <box size="0.11999999731779099 0.11999999731779099 0.11999999731779099"/>
      </geometry>
    </collision>
  </link>
  <joint name="right_hip_pitch_joint" type="revolute">
    <origin xyz="0.0 -0.11535999923944473 0.0" rpy="0.0 0.0 0.0"/>
    <axis xyz="0.0 1.0 0.0"/>
    <parent link="right_hip_roll_link"/>
    <child link="right_hip_pitch_link"/>
    <limit effort="1000.0" lower="-3.140000104904175" upper="2.5300002098083496" velocity="1000.0"/>
  </joint>
  <link name="right_hip_pitch_link">
    <inertial>
      <origin xyz="0.007459999993443489 0.02346000075340271 -0.0819299966096878" rpy="-0.10738416016101837 -0.01352748367935419 0.3884797990322113"/>
      <mass value="4.1519999504089355"/>
      <inertia ixx="0.08295030146837234" ixy="0.0" ixz="0.0" iyy="0.08214569836854935" iyz="0.0" izz="0.005109089892357588"/>
    </inertial>
    <collision name="right_hip_pitch_link_collision">
      <origin xyz="0.0 -0.009999999776482582 -0.1899999976158142" rpy="0.0 0.0 0.0"/>
      <geometry>
        <box size="0.11999999731779099 0.07999999821186066 0.4399999976158142"/>
      </geometry>
    </collision>
  </link>
  <joint name="right_knee_joint" type="revolute">
    <origin xyz="0.0 0.0 -0.4000000059604645" rpy="0.0 0.0 0.0"/>
    <axis xyz="0.0 1.0 0.0"/>
    <parent link="right_hip_pitch_link"/>
    <child link="right_knee_link"/>
    <limit effort="1000.0" lower="-0.2600000202655792" upper="2.049999952316284" velocity="1000.0"/>
  </joint>
  <link name="right_knee_link">
    <inertial>
      <origin xyz="-0.0013599999947473407 0.005119999870657921 -0.13840000331401825" rpy="-0.10783059895038605 -0.0011182109592482448 1.3555643558502197"/>
      <mass value="1.7209999561309814"/>
      <inertia ixx="0.012523699551820755" ixy="0.0" ixz="0.0" iyy="0.012310399673879147" iyz="0.0" izz="0.0019428000086918473"/>
    </inertial>
    <collision name="right_knee_link_collision">
      <origin xyz="0.0 -0.009999999776482582 -0.23000000417232513" rpy="0.0 0.0 0.0"/>
      <geometry>
        <box size="0.10000000149011612 0.07999999821186066 0.3400000035762787"/>
      </geometry>
    </collision>
  </link>
  <joint name="right_ankle_joint" type="revolute">
    <origin xyz="0.0 0.0 -0.4000000059604645" rpy="0.0 0.0 0.0"/>
    <axis xyz="0.0 1.0 0.0"/>
    <parent link="right_knee_link"/>
    <child link="right_ankle_link"/>
    <limit effort="1000.0" lower="-0.8700000047683716" upper="0.5200000405311584" velocity="1000.0"/>
  </joint>
  <link name="right_ankle_link">
    <inertial>
      <origin xyz="0.0485679991543293 0.0 -0.045609001070261" rpy="1.6128175258636475 0.0 1.5707963705062866"/>
      <mass value="0.5524479746818542"/>
      <inertia ixx="0.0036200000904500484" ixy="0.0" ixz="0.0" iyy="0.0035570100881159306" iyz="0.0" izz="0.00014998699771240354"/>
    </inertial>
    <collision name="right_ankle_link_collision_1">
      <origin xyz="0.14499999582767487 0.0 -0.05380000174045563" rpy="0.0 0.0 0.0"/>
      <geometry>
        <box size="0.10999999940395355 0.029600000008940697 0.029999999329447746"/>
      </geometry>
    </collision>
    <collision name="right_ankle_link_collision_2">
      <origin xyz="0.020150000229477882 0.0 -0.03999999910593033" rpy="0.0 0.0 0.0"/>
      <geometry>
        <box size="0.1396999955177307 0.029600000008940697 0.03999999910593033"/>
      </geometry>
    </collision>
    <collision name="right_ankle_link_collision_3">
      <origin xyz="-0.0746999979019165 0.0 -0.05380000174045563" rpy="0.0 0.0 0.0"/>
      <geometry>
        <box size="0.05000000074505806 0.029600000008940697 0.029999999329447746"/>
      </geometry>
    </collision>
  </link>
  <joint name="torso_joint" type="revolute">
    <origin xyz="0.0 0.0 0.0" rpy="0.0 0.0 0.0"/>
    <axis xyz="0.0 0.0 1.0"/>
    <parent link="pelvis"/>
    <child link="torso_link"/>
    <limit effort="1000.0" lower="-2.3499999046325684" upper="2.3499999046325684" velocity="1000.0"/>
  </joint>
  <link name="torso_link">
    <inertial>
      <origin xyz="0.0004889999981969595 0.0027970001101493835 0.20484000444412231" rpy="-0.002596466103568673 -0.0056548817083239555 -0.006974807009100914"/>
      <mass value="17.788999557495117"/>
      <inertia ixx="0.48731499910354614" ixy="0.0" ixz="0.0" iyy="0.4096280038356781" iyz="0.0" izz="0.12783700227737427"/>
    </inertial>
    <collision name="torso_link_collision">
      <origin xyz="0.0 0.0 0.3799999952316284" rpy="0.0 0.0 0.0"/>
      <geometry>
        <box size="0.14000000059604645 0.20999999344348907 0.7400000095367432"/>
      </geometry>
    </collision>
  </link>
  <joint name="left_shoulder_pitch_joint" type="revolute">
    <origin xyz="0.005499999970197678 0.155349999666214 0.4299899935722351" rpy="0.4363292157649994 0.0 0.0"/>
    <axis xyz="0.0 1.0 0.0"/>
    <parent link="torso_link"/>
    <child link="left_shoulder_pitch_link"/>
    <limit effort="1000.0" lower="-2.870000123977661" upper="2.870000123977661" velocity="1000.0"/>
  </joint>
  <link name="left_shoulder_pitch_link">
    <inertial>
      <origin xyz="0.005044999998062849 0.05365699902176857 -0.01571499928832054" rpy="1.2363550662994385 -0.021921830251812935 -0.03857455775141716"/>
      <mass value="1.0329999923706055"/>
      <inertia ixx="0.0012993599520996213" ixy="0.0" ixz="0.0" iyy="0.0009871129877865314" iyz="0.0" izz="0.0008581979782320559"/>
    </inertial>
    <collision name="left_shoulder_pitch_link_collision">
      <origin xyz="0.0 0.05000000074505806 -0.014999999664723873" rpy="0.0 0.0 0.0"/>
      <geometry>
        <box size="0.07000000029802322 0.10000000149011612 0.09000000357627869"/>
      </geometry>
    </collision>
  </link>
  <joint name="left_shoulder_roll_joint" type="revolute">
    <origin xyz="-0.005499999970197678 0.05649999901652336 -0.016499999910593033" rpy="-0.4363291561603546 0.0 0.0"/>
    <axis xyz="1.0 0.0 0.0"/>
    <parent link="left_shoulder_pitch_link"/>
    <child link="left_shoulder_roll_link"/>
    <limit effort="1000.0" lower="-0.3399999737739563" upper="3.1100001335144043" velocity="1000.0"/>
  </joint>
  <link name="left_shoulder_roll_link">
    <inertial>
      <origin xyz="0.000678999989759177 0.0011500000255182385 -0.0940760001540184" rpy="0.1180100366473198 0.10007335245609283 1.4971070289611816"/>
      <mass value="0.7929999828338623"/>
      <inertia ixx="0.0017038800287991762" ixy="0.0" ixz="0.0" iyy="0.0015825600130483508" iyz="0.0" izz="0.0010033600265160203"/>
    </inertial>
    <collision name="left_shoulder_roll_link_collision">
      <origin xyz="0.0 0.0 -0.10999999940395355" rpy="0.0 0.0 0.0"/>
      <geometry>
        <box size="0.10000000149011612 0.10000000149011612 0.035999998450279236"/>
      </geometry>
    </collision>
  </link>
  <joint name="left_shoulder_yaw_joint" type="revolute">
    <origin xyz="0.0 0.0 -0.13429999351501465" rpy="0.0 0.0 0.0"/>
    <axis xyz="0.0 0.0 1.0"/>
    <parent link="left_shoulder_roll_link"/>
    <child link="left_shoulder_yaw_link"/>
    <limit effort="1000.0" lower="-1.2999999523162842" upper="4.449999809265137" velocity="1000.0"/>
  </joint>
  <link name="left_shoulder_yaw_link">
    <inertial>
      <origin xyz="0.013650000095367432 0.002767000114545226 -0.16266000270843506" rpy="-0.1139453873038292 -0.01960502751171589 1.5800683498382568"/>
      <mass value="0.8389999866485596"/>
      <inertia ixx="0.004080379847437143" ixy="0.0" ixz="0.0" iyy="0.003703670110553503" iyz="0.0" izz="0.0006226869882084429"/>
    </inertial>
    <collision name="left_shoulder_yaw_link_collision">
      <origin xyz="0.0 0.0 -0.11999999731779099" rpy="0.0 0.0 0.0"/>
      <geometry>
        <box size="0.05999999865889549 0.05999999865889549 0.23999999463558197"/>
      </geometry>
    </collision>
  </link>
  <joint name="left_elbow_joint" type="revolute">
    <origin xyz="0.01850000023841858 0.0 -0.1979999989271164" rpy="0.0 0.0 0.0"/>
    <axis xyz="0.0 1.0 0.0"/>
    <parent link="left_shoulder_yaw_link"/>
    <child link="left_elbow_link_ball_hand"/>
    <limit effort="1000.0" lower="-1.2500001192092896" upper="2.609999895095825" velocity="1000.0"/>
  </joint>
  <link name="left_elbow_link_ball_hand">
    <inertial>
      <origin xyz="0.15907999873161316 -0.00014400000509340316 -0.015776000916957855" rpy="1.7972631454467773 -1.3357229232788086 1.3568445444107056"/>
      <mass value="0.6690000295639038"/>
      <inertia ixx="0.00601828983053565" ixy="0.0" ixz="0.0" iyy="0.006005790084600449" iyz="0.0" izz="0.0004083050007466227"/>
    </inertial>
    <collision name="left_elbow_link_ball_hand_collision_1">
      <origin xyz="0.15000000596046448 0.0 -0.017999999225139618" rpy="0.0 0.0 0.0"/>
      <geometry>
        <box size="0.23999999463558197 0.05000000074505806 0.05000000074505806"/>
      </geometry>
    </collision>
    <collision name="left_elbow_link_ball_hand_collision_2">
      <origin xyz="0.2800000011920929 0.0 -0.017999999225139618" rpy="0.0 0.0 0.0"/>
      <geometry>
        <sphere radius="0.0364999994635582"/>
      </geometry>
    </collision>
  </link>
  <joint name="right_shoulder_pitch_joint" type="revolute">
    <origin xyz="0.005499999970197678 -0.155349999666214 0.4299899935722351" rpy="-0.4363292157649994 0.0 0.0"/>
    <axis xyz="0.0 1.0 0.0"/>
    <parent link="torso_link"/>
    <child link="right_shoulder_pitch_link"/>
    <limit effort="1000.0" lower="-2.870000123977661" upper="2.870000123977661" velocity="1000.0"/>
  </joint>
  <link name="right_shoulder_pitch_link">
    <inertial>
      <origin xyz="0.005044999998062849 -0.05365699902176857 -0.01571499928832054" rpy="1.9052376747131348 -0.021921830251812935 0.03857455775141716"/>
      <mass value="1.0329999923706055"/>
      <inertia ixx="0.0012993599520996213" ixy="0.0" ixz="0.0" iyy="0.0009871129877865314" iyz="0.0" izz="0.0008581979782320559"/>
    </inertial>
    <collision name="right_shoulder_pitch_link_collision">
      <origin xyz="0.0 -0.05000000074505806 -0.014999999664723873" rpy="0.0 0.0 0.0"/>
      <geometry>
        <box size="0.07000000029802322 0.10000000149011612 0.09000000357627869"/>
      </geometry>
    </collision>
  </link>
  <joint name="right_shoulder_roll_joint" type="revolute">
    <origin xyz="-0.005499999970197678 -0.05649999901652336 -0.016499999910593033" rpy="0.4363291561603546 0.0 0.0"/>
    <axis xyz="1.0 0.0 0.0"/>
    <parent link="right_shoulder_pitch_link"/>
    <child link="right_shoulder_roll_link"/>
    <limit effort="1000.0" lower="-3.1100001335144043" upper="0.3399999737739563" velocity="1000.0"/>
  </joint>
  <link name="right_shoulder_roll_link">
    <inertial>
      <origin xyz="0.000678999989759177 -0.0011500000255182385 -0.0940760001540184" rpy="0.1180100366473198 -0.10007335245609283 1.644485592842102"/>
      <mass value="0.7929999828338623"/>
      <inertia ixx="0.0017038800287991762" ixy="0.0" ixz="0.0" iyy="0.0015825600130483508" iyz="0.0" izz="0.0010033600265160203"/>
    </inertial>
    <collision name="right_shoulder_roll_link_collision">
      <origin xyz="0.0 0.0 -0.10999999940395355" rpy="0.0 0.0 0.0"/>
      <geometry>
        <box size="0.10000000149011612 0.10000000149011612 0.035999998450279236"/>
      </geometry>
    </collision>
  </link>
  <joint name="right_shoulder_yaw_joint" type="revolute">
    <origin xyz="0.0 0.0 -0.13429999351501465" rpy="0.0 0.0 0.0"/>
    <axis xyz="0.0 0.0 1.0"/>
    <parent link="right_shoulder_roll_link"/>
    <child link="right_shoulder_yaw_link"/>
    <limit effort="1000.0" lower="-4.449999809265137" upper="1.2999999523162842" velocity="1000.0"/>
  </joint>
  <link name="right_shoulder_yaw_link">
    <inertial>
      <origin xyz="0.013650000095367432 -0.002767000114545226 -0.16266000270843506" rpy="-0.1139453873038292 0.01960502751171589 1.5615242719650269"/>
      <mass value="0.8389999866485596"/>
      <inertia ixx="0.004080379847437143" ixy="0.0" ixz="0.0" iyy="0.003703670110553503" iyz="0.0" izz="0.0006226869882084429"/>
    </inertial>
    <collision name="right_shoulder_yaw_link_collision">
      <origin xyz="0.0 0.0 -0.11999999731779099" rpy="0.0 0.0 0.0"/>
      <geometry>
        <box size="0.05999999865889549 0.05999999865889549 0.23999999463558197"/>
      </geometry>
    </collision>
  </link>
  <joint name="right_elbow_joint" type="revolute">
    <origin xyz="0.01850000023841858 0.0 -0.1979999989271164" rpy="0.0 0.0 0.0"/>
    <axis xyz="0.0 1.0 0.0"/>
    <parent link="right_shoulder_yaw_link"/>
    <child link="right_elbow_link_ball_hand"/>
    <limit effort="1000.0" lower="-1.2500001192092896" upper="2.609999895095825" velocity="1000.0"/>
  </joint>
  <link name="right_elbow_link_ball_hand">
    <inertial>
      <origin xyz="0.15907999873161316 0.00014400000509340316 -0.015776000916957855" rpy="-1.7972631454467773 -1.3357229232788086 -1.3568445444107056"/>
      <mass value="0.6690000295639038"/>
      <inertia ixx="0.00601828983053565" ixy="0.0" ixz="0.0" iyy="0.006005790084600449" iyz="0.0" izz="0.0004083050007466227"/>
    </inertial>
    <collision name="right_elbow_link_ball_hand_collision_1">
      <origin xyz="0.15000000596046448 0.0 -0.017999999225139618" rpy="0.0 0.0 0.0"/>
      <geometry>
        <box size="0.23999999463558197 0.05000000074505806 0.05000000074505806"/>
      </geometry>
    </collision>
    <collision name="right_elbow_link_ball_hand_collision_2">
      <origin xyz="0.2800000011920929 0.0 -0.017999999225139618" rpy="0.0 0.0 0.0"/>
      <geometry>
        <sphere radius="0.0364999994635582"/>
      </geometry>
    </collision>
  </link>
</robot>