<mujoco model="montessori_box">
    <compiler angle="radian" meshdir="." autolimits="true" />
    <asset>
        <mesh name="MontessoriBox" file="stl/MontessoriBox.stl" />
        <mesh name="MontessoriDrawer" file="stl/MontessoriDrawer.stl" />
        <mesh name="MontessoriDrawerHandle" file="stl/MontessoriDrawerHandle.stl" />
    </asset>
    <default>
        <default class="montessori_box_visual">
            <geom contype="0" conaffinity="0" rgba="0.89 0.67 0.57 1.0"/>
        </default>
        <default class="montessori_box_collision">
            <geom rgba="0.9 0.9 0.9 1.0" group="3"/>
        </default>
    </default>
    <worldbody>
        <body name="montessori_box" pos="0 0 0" quat="1 0 0 0">
            <geom name="MontessoriBox" type="mesh" mesh="MontessoriBox" class="montessori_box_visual"/>
            <geom name="UCX_MontessoriBox_001" type="box" pos="-0.005 -0.044649 0" size="0.06 0.001326 0.033053" class="montessori_box_collision"/>
            <geom name="UCX_MontessoriBox_002" type="box" pos="-0.005 0.044649 0" size="0.06 0.001326 0.033053" class="montessori_box_collision"/>
            <geom name="UCX_MontessoriBox_003" type="box" pos="0.0605 0 0" size="0.0045 0.132621 0.033053" class="montessori_box_collision"/>
            <geom name="UCX_MontessoriBox_004" type="box" pos="0 -0.137621 0" size="0.065 0.005 0.033053" class="montessori_box_collision"/>
            <geom name="UCX_MontessoriBox_005" type="box" pos="0 0.137621 0" size="0.065 0.005 0.033053" class="montessori_box_collision"/>
            <geom name="UCX_MontessoriBox_006" type="box" pos="0 0 -0.038053" size="0.065 0.142621 0.005" class="montessori_box_collision"/>
            <geom name="UCX_MontessoriBox_007" type="box" pos="0 0.12346 0.038053 " size="0.065 0.0191615 0.005" class="montessori_box_collision"/>
            <geom name="UCX_MontessoriBox_008" type="box" pos="0 0.044649 0.038053 " size="0.065 0.029649 0.005" class="montessori_box_collision"/>
            <geom name="UCX_MontessoriBox_009" type="box" pos="0 -0.047149 0.038053 " size="0.065 0.032149 0.005" class="montessori_box_collision"/>
            <geom name="UCX_MontessoriBox_010" type="box" pos="0 -0.12096 0.038053 " size="0.065 0.0216615 0.005" class="montessori_box_collision"/>
            <geom name="UCX_MontessoriBox_011" type="box" pos="0.050243 0.089298 0.038053" size="0.0147815 0.015 0.005" class="montessori_box_collision"/>
            <geom name="UCX_MontessoriBox_012" type="box" pos="0.00597 0.089298 0.038053" size="0.0234915 0.015 0.005" class="montessori_box_collision"/>
            <geom name="UCX_MontessoriBox_013" type="box" pos="-0.056273 0.089298 0.038053" size="0.008751 0.015 0.005" class="montessori_box_collision"/>
            <geom name="UCX_MontessoriBox_014" type="box" pos="-0.017522 0.074298 0.038053" quat="0.9238795 0 0 0.3826834" size="0.006213 0.006213 0.005" class="montessori_box_collision"/>
            <geom name="UCX_MontessoriBox_015" type="box" pos="-0.017522 0.104298 0.038053" quat="0.9238795 0 0 0.3826834" size="0.006213 0.006213 0.005" class="montessori_box_collision"/>
            <geom name="UCX_MontessoriBox_016" type="box" pos="-0.047522 0.104298 0.038053" quat="0.9238795 0 0 0.3826834" size="0.006213 0.006213 0.005" class="montessori_box_collision"/>
            <geom name="UCX_MontessoriBox_017" type="box" pos="-0.047522 0.074298 0.038053" quat="0.9238795 0 0 0.3826834" size="0.006213 0.006213 0.005" class="montessori_box_collision"/>
            <geom name="UCX_MontessoriBox_018" type="box" pos="0.055238 0 0.038053" size="0.009786 0.015 0.005" class="montessori_box_collision"/>
            <geom name="UCX_MontessoriBox_019" type="box" pos="-0.051273 0 0.038053" size="0.013751 0.015 0.005" class="montessori_box_collision"/>
            <geom name="UCX_MontessoriBox_020" type="box" pos="-0.004025 0 0.038053" size="0.0235 0.015 0.005" class="montessori_box_collision"/>
            <geom name="UCX_MontessoriBox_021" type="box" pos="0.039961 -0.02049 0.038053" quat="0.9659258 0 0 0.258819" size="0.015 0.015 0.005" class="montessori_box_collision"/>
            <geom name="UCX_MontessoriBox_022" type="box" pos="0.039961 0.02049 0.038053" quat="0.9659258 0 0 -0.258819" size="0.015 0.015 0.005" class="montessori_box_collision"/>
            <geom name="UCX_MontessoriBox_023" type="box" pos="0.053743 -0.089298 0.038053" size="0.0112815 0.01 0.005" class="montessori_box_collision"/>
            <geom name="UCX_MontessoriBox_024" type="box" pos="0 -0.089298 0.038053" size="0.0224915 0.01 0.005" class="montessori_box_collision"/>
            <geom name="UCX_MontessoriBox_025" type="box" pos="-0.053773 -0.089298 0.038053" size="0.011251 0.01 0.005" class="montessori_box_collision"/>
            <geom name="UCX_MontessoriBox_026" type="box" pos="-0.042522 -0.099298 0.038053" quat="0.9238795 0 0 0.3826834" size="0.004142 0.004142 0.005" class="montessori_box_collision"/>
            <geom name="UCX_MontessoriBox_027" type="box" pos="-0.022522 -0.099298 0.038053" quat="0.9238795 0 0 0.3826834" size="0.004142 0.004142 0.005" class="montessori_box_collision"/>
            <geom name="UCX_MontessoriBox_028" type="box" pos="-0.022522 -0.079298 0.038053" quat="0.9238795 0 0 0.3826834" size="0.004142 0.004142 0.005" class="montessori_box_collision"/>
            <geom name="UCX_MontessoriBox_029" type="box" pos="-0.042522 -0.079298 0.038053" quat="0.9238795 0 0 0.3826834" size="0.004142 0.004142 0.005" class="montessori_box_collision"/>
        
            <body name="montessori_drawer_1" pos="-0.005 0.089298 0">
                <inertial mass="0.16877292096614838" pos="-4.1819294693823394e-09 -4.8547952324895505e-09 -0.0074079083278775215" quat="0.0 0.7071067690849304 0.0 0.7071067690849304" diaginertia="0.00047040951903909445 0.000373675546143204 0.00024498385027982295"/>
                <geom name="MontessoriDrawer1" type="mesh" mesh="MontessoriDrawer" rgba="1.0 0.83 0.67 1.0" class="montessori_box_visual"/>
                <geom name="UCX_MontessoriDrawer1_001" type="box" pos="0 0 -0.030247" size="0.06 0.04289 0.002475" class="montessori_box_collision"/>
                <geom name="UCX_MontessoriDrawer1_002" type="box" pos="0 -0.040415 0.002475" size="0.06 0.0024755 0.030247" class="montessori_box_collision"/>
                <geom name="UCX_MontessoriDrawer1_003" type="box" pos="0 0.040415 0.002475" size="0.06 0.0024755 0.030247" class="montessori_box_collision"/>
                <geom name="UCX_MontessoriDrawer1_004" type="box" pos="-0.057524 0 0.002475" size="0.0025 0.0379395 0.030247" class="montessori_box_collision"/>
                <geom name="UCX_MontessoriDrawer1_005" type="box" pos="0.057524 0 0.002475" size="0.0025 0.0379395 0.030247" class="montessori_box_collision"/>
                <joint name="montessori_drawer_1_joint" type="slide" axis="-1 0 0" range="0 0.1" damping="1"/>

                <body name="montessori_drawer_1_handle" pos="-0.07 0 0" >
                    <geom name="MontessoriDrawerHandle1" type="mesh" mesh="MontessoriDrawerHandle" class="montessori_box_visual"/>
                    <geom name="UCX_MontessoriDrawer1Handle_001" type="cylinder" pos="0.005 0 0" quat="0.707 0 0.707 0" size="0.0025 0.005" class="montessori_box_collision"/>
                    <geom name="UCX_MontessoriDrawer1Handle_002" type="ellipsoid" size="0.005 0.01 0.01" class="montessori_box_collision"/>
                </body>
            </body>

            <body name="montessori_drawer_2" pos="-0.005 0 0">
                <inertial mass="0.16877292096614838" pos="-4.1819294693823394e-09 -4.8547952324895505e-09 -0.0074079083278775215" quat="0.0 0.7071067690849304 0.0 0.7071067690849304" diaginertia="0.00047040951903909445 0.000373675546143204 0.00024498385027982295"/>
                <geom name="MontessoriDrawer2" type="mesh" mesh="MontessoriDrawer" rgba="0.99 0.73 0.55 1.0" class="montessori_box_visual"/>
                <geom name="UCX_MontessoriDrawer2_001" type="box" pos="0 0 -0.030247" size="0.06 0.04289 0.002475" class="montessori_box_collision"/>
                <geom name="UCX_MontessoriDrawer2_002" type="box" pos="0 -0.040415 0.002475" size="0.06 0.0024755 0.030247" class="montessori_box_collision"/>
                <geom name="UCX_MontessoriDrawer2_003" type="box" pos="0 0.040415 0.002475" size="0.06 0.0024755 0.030247" class="montessori_box_collision"/>
                <geom name="UCX_MontessoriDrawer2_004" type="box" pos="-0.057524 0 0.002475" size="0.0025 0.0379395 0.030247" class="montessori_box_collision"/>
                <geom name="UCX_MontessoriDrawer2_005" type="box" pos="0.057524 0 0.002475" size="0.0025 0.0379395 0.030247" class="montessori_box_collision"/>
                <joint name="montessori_drawer_2_joint" type="slide" axis="-1 0 0" range="0 0.1" damping="1"/>

                <body name="montessori_drawer_2_handle" pos="-0.07 0 0" >
                    <geom name="MontessoriDrawerHandle2" type="mesh" mesh="MontessoriDrawerHandle" class="montessori_box_visual"/>
                    <geom name="UCX_MontessoriDrawer2Handle_001" type="cylinder" pos="0.005 0 0" quat="0.707 0 0.707 0" size="0.0025 0.005" class="montessori_box_collision"/>
                    <geom name="UCX_MontessoriDrawer2Handle_002" type="ellipsoid" size="0.005 0.01 0.01" class="montessori_box_collision"/>
                </body>
            </body>

            <body name="montessori_drawer_3" pos="-0.005 -0.089298 0">
                <inertial mass="0.16877292096614838" pos="-4.1819294693823394e-09 -4.8547952324895505e-09 -0.0074079083278775215" quat="0.0 0.7071067690849304 0.0 0.7071067690849304" diaginertia="0.00047040951903909445 0.000373675546143204 0.00024498385027982295"/>
                <geom name="MontessoriDrawer3" type="mesh" mesh="MontessoriDrawer" rgba="0.87 0.94 0.98 1.0" class="montessori_box_visual"/>
                <geom name="UCX_MontessoriDrawer3_001" type="box" pos="0 0 -0.030247" size="0.06 0.04289 0.002475" class="montessori_box_collision"/>
                <geom name="UCX_MontessoriDrawer3_002" type="box" pos="0 -0.040415 0.002475" size="0.06 0.0024755 0.030247" class="montessori_box_collision"/>
                <geom name="UCX_MontessoriDrawer3_003" type="box" pos="0 0.040415 0.002475" size="0.06 0.0024755 0.030247" class="montessori_box_collision"/>
                <geom name="UCX_MontessoriDrawer3_004" type="box" pos="-0.057524 0 0.002475" size="0.0025 0.0379395 0.030247" class="montessori_box_collision"/>
                <geom name="UCX_MontessoriDrawer3_005" type="box" pos="0.057524 0 0.002475" size="0.0025 0.0379395 0.030247" class="montessori_box_collision"/>
                <joint name="montessori_drawer_3_joint" type="slide" axis="-1 0 0" range="0 0.1" damping="1"/>

                <body name="montessori_drawer_3_handle" pos="-0.07 0 0" >
                    <geom name="MontessoriDrawerHandle3" type="mesh" mesh="MontessoriDrawerHandle" class="montessori_box_visual"/>
                    <geom name="UCX_MontessoriDrawer3Handle_001" type="cylinder" pos="0.005 0 0" quat="0.707 0 0.707 0" size="0.0025 0.005" class="montessori_box_collision"/>
                    <geom name="UCX_MontessoriDrawer3Handle_002" type="ellipsoid" size="0.005 0.01 0.01" class="montessori_box_collision"/>
                </body>
            </body>
        </body>
    </worldbody>
</mujoco>